<sdf version='1.6'>
  <model name='solo'>
    <link name='body'>
      <pose frame=''>0 0 0 0 -0 0</pose>
      <inertial>
        <pose frame=''>0 0 0 0 -0 0</pose>
        <mass>1.16115</mass>
        <inertia>
          <ixx>0.00578574</ixx>
          <ixy>0</ixy>
          <ixz>0</ixz>
          <iyy>0.0193811</iyy>
          <iyz>0</iyz>
          <izz>0.0247612</izz>
        </inertia>
      </inertial>
      <collision name='body_collision'>
        <pose frame=''>0 0 0 0 -0 0</pose>
        <geometry>
          <mesh>
            <scale>1 1 1</scale>
            <uri>file:///home/prakhargoel/Desktop/Mitacs/QuadSdk/catkin_ws/src/quad-sdk/quad_simulator/solo_description/meshes/stl/solo12/solo_12_base.stl</uri>
          </mesh>
        </geometry>
        <surface>
          <contact>
            <ode>
              <kp>1e+07</kp>
              <kd>1</kd>
              <max_vel>0</max_vel>
              <min_depth>0.001</min_depth>
            </ode>
          </contact>
          <friction>
            <ode>
              <mu>4</mu>
              <mu2>4</mu2>
            </ode>
          </friction>
        </surface>
      </collision>
      <visual name='body_visual'>
        <pose frame=''>0 0 0 0 -0 0</pose>
        <geometry>
          <mesh>
            <scale>1 1 1</scale>
            <uri>file:///home/prakhargoel/Desktop/Mitacs/QuadSdk/catkin_ws/src/quad-sdk/quad_simulator/solo_description/meshes/stl/solo12/solo_12_base.stl</uri>
          </mesh>
        </geometry>
        <material>
          <script>
            <name>Gazebo/White</name>
            <uri>file://media/materials/scripts/gazebo.material</uri>
          </script>
        </material>
      </visual>
      <velocity_decay/>
      <gravity>1</gravity>
      <sensor name='imu_sensor' type='imu'>
        <always_on>1</always_on>
        <visualize>1</visualize>
        <topic>__default_topic_</topic>
        <plugin name='imu_plugin' filename='libgazebo_ros_imu_sensor.so'>
          <topicName>imu</topicName>
          <bodyName>body</bodyName>
          <updateRateHZ>500.0</updateRateHZ>
          <gaussianNoise>0.0</gaussianNoise>
          <xyzOffset>0 0 0</xyzOffset>
          <rpyOffset>0 0 0</rpyOffset>
          <frameName>body</frameName>
          <initialOrientationAsReference>1</initialOrientationAsReference>
        </plugin>
        <pose frame=''>0 0 0 0 -0 0</pose>
      </sensor>
      <gravity>1</gravity>
      <velocity_decay/>
    </link>
    <link name='hip0'>
      <pose frame=''>0.1946 0.0875 0 0 -0 0</pose>
      <inertial>
        <pose frame=''>-0.078707 0.01 0 0 -0 0</pose>
        <mass>0.148538</mass>
        <inertia>
          <ixx>3.024e-05</ixx>
          <ixy>4.671e-05</ixy>
          <ixz>0</ixz>
          <iyy>0.00041193</iyy>
          <iyz>0</iyz>
          <izz>0.00041107</izz>
        </inertia>
      </inertial>
      <collision name='hip0_collision'>
        <pose frame=''>0.0195 0 0 0 -0 0</pose>
        <geometry>
          <mesh>
            <scale>1 1 1</scale>
            <uri>file:///home/prakhargoel/Desktop/Mitacs/QuadSdk/catkin_ws/src/quad-sdk/quad_simulator/solo_description/meshes/stl/solo12/solo12_hip_fe_fl.stl</uri>
          </mesh>
        </geometry>
        <surface>
          <contact>
            <ode>
              <kp>1e+07</kp>
              <kd>1</kd>
              <max_vel>0</max_vel>
              <min_depth>0.001</min_depth>
            </ode>
          </contact>
          <friction>
            <ode>
              <mu>4</mu>
              <mu2>4</mu2>
            </ode>
          </friction>
        </surface>
      </collision>
      <visual name='hip0_visual'>
        <pose frame=''>0.0195 0 0 0 -0 0</pose>
        <geometry>
          <mesh>
            <scale>1 1 1</scale>
            <uri>file:///home/prakhargoel/Desktop/Mitacs/QuadSdk/catkin_ws/src/quad-sdk/quad_simulator/solo_description/meshes/stl/solo12/solo12_hip_fe_fl.stl</uri>
          </mesh>
        </geometry>
        <material>
          <script>
            <name>Gazebo/Grey</name>
            <uri>file://media/materials/scripts/gazebo.material</uri>
          </script>
        </material>
      </visual>
      <velocity_decay/>
      <gravity>1</gravity>
      <velocity_decay/>
    </link>
    <joint name='8' type='revolute'>
      <child>hip0</child>
      <parent>body</parent>
      <axis>
        <xyz>1 0 0</xyz>
        <limit>
          <lower>-10</lower>
          <upper>10</upper>
          <effort>1000</effort>
          <velocity>1000</velocity>
        </limit>
        <dynamics>
          <damping>0</damping>
          <friction>0</friction>
          <spring_reference>0</spring_reference>
          <spring_stiffness>0</spring_stiffness>
        </dynamics>
        <use_parent_model_frame>0</use_parent_model_frame>
      </axis>
    </joint>
 <link name='upper0'>
      <pose frame=''>0.1946 0.1015 0 0 -0 0</pose>
      <inertial>
        <pose frame=''>1.4e-05 0.019359 -0.078707 0 -0 0</pose>
        <mass>0.148538</mass>
        <inertia>
          <ixx>0.00041107</ixx>
          <ixy>0</ixy>
          <ixz>0</ixz>
          <iyy>0.00041193</iyy>
          <iyz>4.671e-05</iyz>
          <izz>3.024e-05</izz>
        </inertia>
      </inertial>
      <collision name='upper0_collision'>
        <pose frame=''>0 0 0 0 -0 0</pose>
        <geometry>
          <mesh>
            <scale>1 1 1</scale>
            <uri>file:///home/prakhargoel/Desktop/Mitacs/QuadSdk/catkin_ws/src/quad-sdk/quad_simulator/solo_description/meshes/stl/with_foot/solo_upper_leg_left_side.stl</uri>
          </mesh>
        </geometry>
        <surface>
          <contact>
            <ode>
              <kp>1e+07</kp>
              <kd>1</kd>
              <max_vel>0</max_vel>
              <min_depth>0.001</min_depth>
            </ode>
          </contact>
          <friction>
            <ode>
              <mu>4</mu>
              <mu2>4</mu2>
            </ode>
          </friction>
        </surface>
      </collision>
      <visual name='upper0_visual'>
        <pose frame=''>0 0 0 0 -0 0</pose>
        <geometry>
          <mesh>
            <scale>1 1 1</scale>
            <uri>file:///home/prakhargoel/Desktop/Mitacs/QuadSdk/catkin_ws/src/quad-sdk/quad_simulator/solo_description/meshes/stl/with_foot/solo_upper_leg_left_side.stl</uri>
          </mesh>
        </geometry>
        <material>
          <script>
            <name>Gazebo/Grey</name>
            <uri>file://media/materials/scripts/gazebo.material</uri>
          </script>
        </material>
      </visual>
      <velocity_decay/>
      <gravity>1</gravity>
      <velocity_decay/>
    </link>
<joint name='0' type='revolute'>
      <child>upper0</child>
      <parent>hip0</parent>
      <axis>
        <xyz>0 1 0</xyz>
        <limit>
          <lower>-10</lower>
          <upper>10</upper>
          <effort>1000</effort>
          <velocity>1000</velocity>
        </limit>
        <dynamics>
          <damping>0</damping>
          <friction>0</friction>
          <spring_reference>0</spring_reference>
          <spring_stiffness>0</spring_stiffness>
        </dynamics>
        <use_parent_model_frame>0</use_parent_model_frame>
      </axis>
    </joint>
<link name='lower0'>
      <pose frame=''>0.1946 0.13895 -0.16 0 -0 0</pose>
      <inertial>
        <pose frame=''>0 0.007899 -0.102249 0 -0 0</pose>
        <mass>0.0376361</mass>
        <inertia>
          <ixx>0.000148819</ixx>
          <ixy>0</ixy>
          <ixz>0</ixz>
          <iyy>0.000149139</iyy>
          <iyz>3.09919e-06</iyz>
          <izz>2.69009e-06</izz>
        </inertia>
      </inertial>
      <collision name='lower0_collision'>
        <pose frame=''>0 0 0 0 -0 0</pose>
        <geometry>
          <mesh>
            <scale>1 1 1</scale>
            <uri>file:///home/prakhargoel/Desktop/Mitacs/QuadSdk/catkin_ws/src/quad-sdk/quad_simulator/solo_description/meshes/stl/with_foot/solo_lower_leg_left_side.stl</uri>
          </mesh>
        </geometry>
        <surface>
          <contact>
            <ode>
              <kp>1e+07</kp>
              <kd>1</kd>
              <max_vel>0</max_vel>
              <min_depth>0.001</min_depth>
            </ode>
          </contact>
          <friction>
            <ode>
              <mu>4</mu>
              <mu2>4</mu2>
            </ode>
          </friction>
        </surface>
      </collision>
      <collision name='lower0_fixed_joint_lump__toe0_collision_1'>
        <pose frame=''>0 0.008 -0.16 0 -0 0</pose>
        <geometry>
          <mesh>
            <scale>1 1 1</scale>
            <uri>file:///home/prakhargoel/Desktop/Mitacs/QuadSdk/catkin_ws/src/quad-sdk/quad_simulator/solo_description/meshes/stl/with_foot/solo_foot.stl</uri>
          </mesh>
        </geometry>
        <surface>
          <bounce>
            <restitution_coefficient>0</restitution_coefficient>
            <threshold>1e+06</threshold>
          </bounce>
          <friction>
            <ode>
              <mu>0.5</mu>
              <mu2>0.5</mu2>
            </ode>
            <bullet>
              <rolling_friction>0.3</rolling_friction>
              <friction2>50</friction2>
            </bullet>
          </friction>
          <contact>
            <bullet>
              <kp>30000</kp>
              <kd>1000</kd>
              <split_impulse>1</split_impulse>
              <split_impulse_penetration_threshold>-0.01</split_impulse_penetration_threshold>
            </bullet>
            <ode>
              <kp>30000</kp>
              <kd>1000</kd>
            </ode>
          </contact>
        </surface>
      </collision>
      <visual name='lower0_visual'>
        <pose frame=''>0 0 0 0 -0 0</pose>
        <geometry>
          <mesh>
            <scale>1 1 1</scale>
            <uri>file:///home/prakhargoel/Desktop/Mitacs/QuadSdk/catkin_ws/src/quad-sdk/quad_simulator/solo_description/meshes/stl/with_foot/solo_lower_leg_left_side.stl</uri>
          </mesh>
        </geometry>
        <material>
          <script>
            <name>Gazebo/Grey</name>
            <uri>file://media/materials/scripts/gazebo.material</uri>
          </script>
        </material>
      </visual>
      <visual name='lower0_fixed_joint_lump__toe0_visual_1'>
        <pose frame=''>0 0.008 -0.16 0 -0 0</pose>
        <geometry>
          <mesh>
            <scale>1 1 1</scale>
            <uri>file:///home/prakhargoel/Desktop/Mitacs/QuadSdk/catkin_ws/src/quad-sdk/quad_simulator/solo_description/meshes/stl/with_foot/solo_foot.stl</uri>
          </mesh>
        </geometry>
        <material>
          <script>
            <name>Gazebo/DarkGray</name>
            <uri>file://media/materials/scripts/gazebo.material</uri>
          </script>
        </material>
      </visual>
      <velocity_decay/>
      <velocity_decay/>
      <gravity>1</gravity>
      <velocity_decay/>
    </link>
    <joint name='1' type='revolute'>
      <child>lower0</child>
      <parent>upper0</parent>
      <axis>
        <xyz>0 1 0</xyz>
        <limit>
          <lower>-10</lower>
          <upper>10</upper>
          <effort>1000</effort>
          <velocity>1000</velocity>
        </limit>
        <dynamics>
          <damping>0</damping>
          <friction>0</friction>
          <spring_reference>0</spring_reference>
          <spring_stiffness>0</spring_stiffness>
        </dynamics>
        <use_parent_model_frame>0</use_parent_model_frame>
      </axis>
    </joint>
 

    <link name='hip1'>
      <pose frame=''>-0.1946 0.0875 0 0 -0 0</pose>
      <inertial>
        <pose frame=''>0.078707 0.01 0 0 -0 0</pose>
        <mass>0.148538</mass>
        <inertia>
          <ixx>3.024e-05</ixx>
          <ixy>4.671e-05</ixy>
          <ixz>0</ixz>
          <iyy>0.00041193</iyy>
          <iyz>0</iyz>
          <izz>0.00041107</izz>
        </inertia>
      </inertial>
      <collision name='hip1_collision'>
        <pose frame=''>-0.0195 0 0 0 -0 0</pose>
        <geometry>
          <mesh>
            <scale>1 1 1</scale>
            <uri>file:///home/prakhargoel/Desktop/Mitacs/QuadSdk/catkin_ws/src/quad-sdk/quad_simulator/solo_description/meshes/stl/solo12/solo12_hip_fe_hl.stl</uri>
          </mesh>
        </geometry>
        <surface>
          <contact>
            <ode>
              <kp>1e+07</kp>
              <kd>1</kd>
              <max_vel>0</max_vel>
              <min_depth>0.001</min_depth>
            </ode>
          </contact>
          <friction>
            <ode>
              <mu>4</mu>
              <mu2>4</mu2>
            </ode>
          </friction>
        </surface>
      </collision>
      <visual name='hip1_visual'>
        <pose frame=''>-0.0195 0 0 0 -0 0</pose>
        <geometry>
          <mesh>
            <scale>1 1 1</scale>
            <uri>file:///home/prakhargoel/Desktop/Mitacs/QuadSdk/catkin_ws/src/quad-sdk/quad_simulator/solo_description/meshes/stl/solo12/solo12_hip_fe_hl.stl</uri>
          </mesh>
        </geometry>
        <material>
          <script>
            <name>Gazebo/DarkGrey</name>
            <uri>file://media/materials/scripts/gazebo.material</uri>
          </script>
        </material>
      </visual>
      <velocity_decay/>
      <gravity>1</gravity>
      <velocity_decay/>
    </link>
    <joint name='9' type='revolute'>
      <child>hip1</child>
      <parent>body</parent>
      <axis>
        <xyz>1 0 0</xyz>
        <limit>
          <lower>-10</lower>
          <upper>10</upper>
          <effort>1000</effort>
          <velocity>1000</velocity>
        </limit>
        <dynamics>
          <damping>0</damping>
          <friction>0</friction>
          <spring_reference>0</spring_reference>
          <spring_stiffness>0</spring_stiffness>
        </dynamics>
        <use_parent_model_frame>0</use_parent_model_frame>
      </axis>
    </joint>
    <link name='upper1'>
      <pose frame=''>-0.1946 0.1015 0 0 -0 0</pose>
      <inertial>
        <pose frame=''>1.4e-05 0.019359 -0.078707 0 -0 0</pose>
        <mass>0.148538</mass>
        <inertia>
          <ixx>0.00041107</ixx>
          <ixy>0</ixy>
          <ixz>0</ixz>
          <iyy>0.00041193</iyy>
          <iyz>4.671e-05</iyz>
          <izz>3.024e-05</izz>
        </inertia>
      </inertial>
      <collision name='upper1_collision'>
        <pose frame=''>0 0 0 0 -0 0</pose>
        <geometry>
          <mesh>
            <scale>1 1 1</scale>
            <uri>file:///home/prakhargoel/Desktop/Mitacs/QuadSdk/catkin_ws/src/quad-sdk/quad_simulator/solo_description/meshes/stl/with_foot/solo_upper_leg_left_side.stl</uri>
          </mesh>
        </geometry>
        <surface>
          <contact>
            <ode>
              <kp>1e+07</kp>
              <kd>1</kd>
              <max_vel>0</max_vel>
              <min_depth>0.001</min_depth>
            </ode>
          </contact>
          <friction>
            <ode>
              <mu>4</mu>
              <mu2>4</mu2>
            </ode>
          </friction>
        </surface>
      </collision>
      <visual name='upper1_visual'>
        <pose frame=''>0 0 0 0 -0 0</pose>
        <geometry>
          <mesh>
            <scale>1 1 1</scale>
            <uri>file:///home/prakhargoel/Desktop/Mitacs/QuadSdk/catkin_ws/src/quad-sdk/quad_simulator/solo_description/meshes/stl/with_foot/solo_upper_leg_left_side.stl</uri>
          </mesh>
        </geometry>
        <material>
          <script>
            <name>Gazebo/DarkGrey</name>
            <uri>file://media/materials/scripts/gazebo.material</uri>
          </script>
        </material>
      </visual>
      <velocity_decay/>
      <gravity>1</gravity>
      <velocity_decay/>
    </link>
    <joint name='2' type='revolute'>
      <child>upper1</child>
      <parent>hip1</parent>
      <axis>
        <xyz>0 1 0</xyz>
        <limit>
          <lower>-10</lower>
          <upper>10</upper>
          <effort>1000</effort>
          <velocity>1000</velocity>
        </limit>
        <dynamics>
          <damping>0</damping>
          <friction>0</friction>
          <spring_reference>0</spring_reference>
          <spring_stiffness>0</spring_stiffness>
        </dynamics>
        <use_parent_model_frame>0</use_parent_model_frame>
      </axis>
    </joint>
    <link name='lower1'>
      <pose frame=''>-0.1946 0.13895 -0.16 0 -0 0</pose>
      <inertial>
        <pose frame=''>0 0.007899 -0.102249 0 -0 0</pose>
        <mass>0.0376361</mass>
        <inertia>
          <ixx>0.000148819</ixx>
          <ixy>0</ixy>
          <ixz>0</ixz>
          <iyy>0.000149139</iyy>
          <iyz>3.09919e-06</iyz>
          <izz>2.69009e-06</izz>
        </inertia>
      </inertial>
      <collision name='lower1_collision'>
        <pose frame=''>0 0 0 0 -0 0</pose>
        <geometry>
          <mesh>
            <scale>1 1 1</scale>
            <uri>file:///home/prakhargoel/Desktop/Mitacs/QuadSdk/catkin_ws/src/quad-sdk/quad_simulator/solo_description/meshes/stl/with_foot/solo_lower_leg_left_side.stl</uri>
          </mesh>
        </geometry>
        <surface>
          <contact>
            <ode>
              <kp>1e+07</kp>
              <kd>1</kd>
              <max_vel>0</max_vel>
              <min_depth>0.001</min_depth>
            </ode>
          </contact>
          <friction>
            <ode>
              <mu>4</mu>
              <mu2>4</mu2>
            </ode>
          </friction>
        </surface>
      </collision>
      <collision name='lower1_fixed_joint_lump__toe1_collision_1'>
        <pose frame=''>0 0.008 -0.16 0 -0 0</pose>
        <geometry>
          <mesh>
            <scale>1 1 1</scale>
            <uri>file:///home/prakhargoel/Desktop/Mitacs/QuadSdk/catkin_ws/src/quad-sdk/quad_simulator/solo_description/meshes/stl/with_foot/solo_foot.stl</uri>
          </mesh>
        </geometry>
        <surface>
          <bounce>
            <restitution_coefficient>0</restitution_coefficient>
            <threshold>1e+06</threshold>
          </bounce>
          <friction>
            <ode>
              <mu>0.5</mu>
              <mu2>0.5</mu2>
            </ode>
            <bullet>
              <rolling_friction>0.3</rolling_friction>
              <friction2>50</friction2>
            </bullet>
          </friction>
          <contact>
            <bullet>
              <kp>30000</kp>
              <kd>1000</kd>
              <split_impulse>1</split_impulse>
              <split_impulse_penetration_threshold>-0.01</split_impulse_penetration_threshold>
            </bullet>
            <ode>
              <kp>30000</kp>
              <kd>1000</kd>
            </ode>
          </contact>
        </surface>
      </collision>
      <visual name='lower1_visual'>
        <pose frame=''>0 0 0 0 -0 0</pose>
        <geometry>
          <mesh>
            <scale>1 1 1</scale>
            <uri>file:///home/prakhargoel/Desktop/Mitacs/QuadSdk/catkin_ws/src/quad-sdk/quad_simulator/solo_description/meshes/stl/with_foot/solo_lower_leg_left_side.stl</uri>
          </mesh>
        </geometry>
        <material>
          <script>
            <name>Gazebo/Grey</name>
            <uri>file://media/materials/scripts/gazebo.material</uri>
          </script>
        </material>
      </visual>
      <visual name='lower1_fixed_joint_lump__toe1_visual_1'>
        <pose frame=''>0 0.008 -0.16 0 -0 0</pose>
        <geometry>
          <mesh>
            <scale>1 1 1</scale>
            <uri>file:///home/prakhargoel/Desktop/Mitacs/QuadSdk/catkin_ws/src/quad-sdk/quad_simulator/solo_description/meshes/stl/with_foot/solo_foot.stl</uri>
          </mesh>
        </geometry>
        <material>
          <script>
            <name>Gazebo/DarkGray</name>
            <uri>file://media/materials/scripts/gazebo.material</uri>
          </script>
        </material>
      </visual>
      <velocity_decay/>
      <velocity_decay/>
      <gravity>1</gravity>
      <velocity_decay/>
    </link>
    <joint name='3' type='revolute'>
      <child>lower1</child>
      <parent>upper1</parent>
      <axis>
        <xyz>0 1 0</xyz>
        <limit>
          <lower>-10</lower>
          <upper>10</upper>
          <effort>1000</effort>
          <velocity>1000</velocity>
        </limit>
        <dynamics>
          <damping>0</damping>
          <friction>0</friction>
          <spring_reference>0</spring_reference>
          <spring_stiffness>0</spring_stiffness>
        </dynamics>
        <use_parent_model_frame>0</use_parent_model_frame>
      </axis>
    </joint>
    <link name='hip2'>
      <pose frame=''>0.1946 -0.0875 0 0 -0 0</pose>
      <inertial>
        <pose frame=''>-0.078707 -0.01 0 0 -0 0</pose>
        <mass>0.148538</mass>
        <inertia>
          <ixx>3.024e-05</ixx>
          <ixy>-4.671e-05</ixy>
          <ixz>0</ixz>
          <iyy>0.00041193</iyy>
          <iyz>0</iyz>
          <izz>0.00041107</izz>
        </inertia>
      </inertial>
      <collision name='hip2_collision'>
        <pose frame=''>0.0195 0 0 0 -0 0</pose>
        <geometry>
          <mesh>
            <scale>1 1 1</scale>
            <uri>file:///home/prakhargoel/Desktop/Mitacs/QuadSdk/catkin_ws/src/quad-sdk/quad_simulator/solo_description/meshes/stl/solo12/solo12_hip_fe_fr.stl</uri>
          </mesh>
        </geometry>
        <surface>
          <contact>
            <ode>
              <kp>1e+07</kp>
              <kd>1</kd>
              <max_vel>0</max_vel>
              <min_depth>0.001</min_depth>
            </ode>
          </contact>
          <friction>
            <ode>
              <mu>4</mu>
              <mu2>4</mu2>
            </ode>
          </friction>
        </surface>
      </collision>
      <visual name='hip2_visual'>
        <pose frame=''>0.0195 0 0 0 -0 0</pose>
        <geometry>
          <mesh>
            <scale>1 1 1</scale>
            <uri>file:///home/prakhargoel/Desktop/Mitacs/QuadSdk/catkin_ws/src/quad-sdk/quad_simulator/solo_description/meshes/stl/solo12/solo12_hip_fe_fr.stl</uri>
          </mesh>
        </geometry>
        <material>
          <script>
            <name>Gazebo/Grey</name>
            <uri>file://media/materials/scripts/gazebo.material</uri>
          </script>
        </material>
      </visual>
      <velocity_decay/>
      <gravity>1</gravity>
      <velocity_decay/>
    </link>
    <joint name='10' type='revolute'>
      <child>hip2</child>
      <parent>body</parent>
      <axis>
        <xyz>1 0 0</xyz>
        <limit>
          <lower>-10</lower>
          <upper>10</upper>
          <effort>1000</effort>
          <velocity>1000</velocity>
        </limit>
        <dynamics>
          <damping>0</damping>
          <friction>0</friction>
          <spring_reference>0</spring_reference>
          <spring_stiffness>0</spring_stiffness>
        </dynamics>
        <use_parent_model_frame>0</use_parent_model_frame>
      </axis>
    </joint>
   <link name='upper2'>
      <pose frame=''>0.1946 -0.1015 0 0 -0 0</pose>
      <inertial>
        <pose frame=''>-1.4e-05 -0.019359 -0.078707 0 -0 0</pose>
        <mass>0.148538</mass>
        <inertia>
          <ixx>0.00041107</ixx>
          <ixy>0</ixy>
          <ixz>0</ixz>
          <iyy>0.00041193</iyy>
          <iyz>-4.671e-05</iyz>
          <izz>3.024e-05</izz>
        </inertia>
      </inertial>
      <collision name='upper2_collision'>
        <pose frame=''>0 0 0 0 -0 0</pose>
        <geometry>
          <mesh>
            <scale>1 1 1</scale>
            <uri>file:///home/prakhargoel/Desktop/Mitacs/QuadSdk/catkin_ws/src/quad-sdk/quad_simulator/solo_description/meshes/stl/with_foot/solo_upper_leg_right_side.stl</uri>
          </mesh>
        </geometry>
        <surface>
          <contact>
            <ode>
              <kp>1e+07</kp>
              <kd>1</kd>
              <max_vel>0</max_vel>
              <min_depth>0.001</min_depth>
            </ode>
          </contact>
          <friction>
            <ode>
              <mu>4</mu>
              <mu2>4</mu2>
            </ode>
          </friction>
        </surface>
      </collision>
      <visual name='upper2_visual'>
        <pose frame=''>0 0 0 0 -0 0</pose>
        <geometry>
          <mesh>
            <scale>1 1 1</scale>
            <uri>file:///home/prakhargoel/Desktop/Mitacs/QuadSdk/catkin_ws/src/quad-sdk/quad_simulator/solo_description/meshes/stl/with_foot/solo_upper_leg_right_side.stl</uri>
          </mesh>
        </geometry>
        <material>
          <script>
            <name>Gazebo/DarkGrey</name>
            <uri>file://media/materials/scripts/gazebo.material</uri>
          </script>
        </material>
      </visual>
      <velocity_decay/>
      <gravity>1</gravity>
      <velocity_decay/>
    </link>
    <joint name='4' type='revolute'>
      <child>upper2</child>
      <parent>hip2</parent>
      <axis>
        <xyz>0 1 0</xyz>
        <limit>
          <lower>-10</lower>
          <upper>10</upper>
          <effort>1000</effort>
          <velocity>1000</velocity>
        </limit>
        <dynamics>
          <damping>0</damping>
          <friction>0</friction>
          <spring_reference>0</spring_reference>
          <spring_stiffness>0</spring_stiffness>
        </dynamics>
        <use_parent_model_frame>0</use_parent_model_frame>
      </axis>
    </joint>
    <link name='lower2'>
      <pose frame=''>0.1946 -0.13895 -0.16 0 -0 0</pose>
      <inertial>
        <pose frame=''>0 0.004951 -0.102249 0 -0 0</pose>
        <mass>0.0376361</mass>
        <inertia>
          <ixx>0.000150245</ixx>
          <ixy>0</ixy>
          <ixz>0</ixz>
          <iyy>0.000149139</iyy>
          <iyz>-9.37015e-06</iyz>
          <izz>4.11611e-06</izz>
        </inertia>
      </inertial>
      <collision name='lower2_collision'>
        <pose frame=''>0 0 0 0 -0 0</pose>
        <geometry>
          <mesh>
            <scale>1 1 1</scale>
            <uri>file:///home/prakhargoel/Desktop/Mitacs/QuadSdk/catkin_ws/src/quad-sdk/quad_simulator/solo_description/meshes/stl/with_foot/solo_lower_leg_right_side.stl</uri>
          </mesh>
        </geometry>
        <surface>
          <contact>
            <ode>
              <kp>1e+07</kp>
              <kd>1</kd>
              <max_vel>0</max_vel>
              <min_depth>0.001</min_depth>
            </ode>
          </contact>
          <friction>
            <ode>
              <mu>4</mu>
              <mu2>4</mu2>
            </ode>
          </friction>
        </surface>
      </collision>
      <collision name='lower2_fixed_joint_lump__toe1_collision_1'>
        <pose frame=''>0 -0.008 -0.16 0 -0 0</pose>
        <geometry>
          <mesh>
            <scale>1 1 1</scale>
            <uri>file:///home/prakhargoel/Desktop/Mitacs/QuadSdk/catkin_ws/src/quad-sdk/quad_simulator/solo_description/meshes/stl/with_foot/solo_foot.stl</uri>
          </mesh>
        </geometry>
        <surface>
          <bounce>
            <restitution_coefficient>0</restitution_coefficient>
            <threshold>1e+06</threshold>
          </bounce>
          <friction>
            <ode>
              <mu>0.5</mu>
              <mu2>0.5</mu2>
            </ode>
            <bullet>
              <rolling_friction>0.3</rolling_friction>
              <friction2>50</friction2>
            </bullet>
          </friction>
          <contact>
            <bullet>
              <kp>30000</kp>
              <kd>1000</kd>
              <split_impulse>1</split_impulse>
              <split_impulse_penetration_threshold>-0.01</split_impulse_penetration_threshold>
            </bullet>
            <ode>
              <kp>30000</kp>
              <kd>1000</kd>
            </ode>
          </contact>
        </surface>
      </collision>
      <visual name='lower2_visual'>
        <pose frame=''>0 0 0 0 -0 0</pose>
        <geometry>
          <mesh>
            <scale>1 1 1</scale>
            <uri>file:///home/prakhargoel/Desktop/Mitacs/QuadSdk/catkin_ws/src/quad-sdk/quad_simulator/solo_description/meshes/stl/with_foot/solo_lower_leg_right_side.stl</uri>
          </mesh>
        </geometry>
        <material>
          <script>
            <name>Gazebo/DarkGrey</name>
            <uri>file://media/materials/scripts/gazebo.material</uri>
          </script>
        </material>
      </visual>
      <visual name='lower2_fixed_joint_lump__toe1_visual_1'>
        <pose frame=''>0 -0.008 -0.16 0 -0 0</pose>
        <geometry>
          <mesh>
            <scale>1 1 1</scale>
            <uri>file:///home/prakhargoel/Desktop/Mitacs/QuadSdk/catkin_ws/src/quad-sdk/quad_simulator/solo_description/meshes/stl/with_foot/solo_foot.stl</uri>
          </mesh>
        </geometry>
        <material>
          <script>
            <name>Gazebo/DarkGray</name>
            <uri>file://media/materials/scripts/gazebo.material</uri>
          </script>
        </material>
      </visual>
      <velocity_decay/>
      <velocity_decay/>
      <gravity>1</gravity>
      <velocity_decay/>
    </link>
    <joint name='5' type='revolute'>
      <child>lower2</child>
      <parent>upper2</parent>
      <axis>
        <xyz>0 1 0</xyz>
        <limit>
          <lower>-10</lower>
          <upper>10</upper>
          <effort>1000</effort>
          <velocity>1000</velocity>
        </limit>
        <dynamics>
          <damping>0</damping>
          <friction>0</friction>
          <spring_reference>0</spring_reference>
          <spring_stiffness>0</spring_stiffness>
        </dynamics>
        <use_parent_model_frame>0</use_parent_model_frame>
      </axis>
    </joint>
    <link name='hip3'>
      <pose frame=''>-0.1946 -0.0875 0 0 -0 0</pose>
      <inertial>
        <pose frame=''>0.078707 -0.01 0 0 -0 0</pose>
        <mass>0.148538</mass>
        <inertia>
          <ixx>3.024e-05</ixx>
          <ixy>-4.671e-05</ixy>
          <ixz>0</ixz>
          <iyy>0.00041193</iyy>
          <iyz>0</iyz>
          <izz>0.00041107</izz>
        </inertia>
      </inertial>
      <collision name='hip3_collision'>
        <pose frame=''>-0.0195 0 0 0 -0 0</pose>
        <geometry>
          <mesh>
            <scale>1 1 1</scale>
            <uri>file:///home/prakhargoel/Desktop/Mitacs/QuadSdk/catkin_ws/src/quad-sdk/quad_simulator/solo_description/meshes/stl/solo12/solo12_hip_fe_hr.stl</uri>
          </mesh>
        </geometry>
        <surface>
          <contact>
            <ode>
              <kp>1e+07</kp>
              <kd>1</kd>
              <max_vel>0</max_vel>
              <min_depth>0.001</min_depth>
            </ode>
          </contact>
          <friction>
            <ode>
              <mu>4</mu>
              <mu2>4</mu2>
            </ode>
          </friction>
        </surface>
      </collision>
      <visual name='hip3_visual'>
        <pose frame=''>-0.0195 0 0 0 -0 0</pose>
        <geometry>
          <mesh>
            <scale>1 1 1</scale>
            <uri>file:///home/prakhargoel/Desktop/Mitacs/QuadSdk/catkin_ws/src/quad-sdk/quad_simulator/solo_description/meshes/stl/solo12/solo12_hip_fe_hr.stl</uri>
          </mesh>
        </geometry>
        <material>
          <script>
            <name>Gazebo/Grey</name>
            <uri>file://media/materials/scripts/gazebo.material</uri>
          </script>
        </material>
      </visual>
      <velocity_decay/>
      <gravity>1</gravity>
      <velocity_decay/>
    </link>
    <joint name='11' type='revolute'>
      <child>hip3</child>
      <parent>body</parent>
      <axis>
        <xyz>1 0 0</xyz>
        <limit>
          <lower>-10</lower>
          <upper>10</upper>
          <effort>1000</effort>
          <velocity>1000</velocity>
        </limit>
        <dynamics>
          <damping>0</damping>
          <friction>0</friction>
          <spring_reference>0</spring_reference>
          <spring_stiffness>0</spring_stiffness>
        </dynamics>
        <use_parent_model_frame>0</use_parent_model_frame>
      </axis>
    </joint>
    <link name='upper3'>
      <pose frame=''>-0.1946 -0.1015 0 0 -0 0</pose>
      <inertial>
        <pose frame=''>-1.4e-05 -0.019359 -0.078707 0 -0 0</pose>
        <mass>0.148538</mass>
        <inertia>
          <ixx>0.00041107</ixx>
          <ixy>0</ixy>
          <ixz>0</ixz>
          <iyy>0.00041193</iyy>
          <iyz>-4.671e-05</iyz>
          <izz>3.024e-05</izz>
        </inertia>
      </inertial>
      <collision name='upper3_collision'>
        <pose frame=''>0 0 0 0 -0 0</pose>
        <geometry>
          <mesh>
            <scale>1 1 1</scale>
            <uri>file:///home/prakhargoel/Desktop/Mitacs/QuadSdk/catkin_ws/src/quad-sdk/quad_simulator/solo_description/meshes/stl/with_foot/solo_upper_leg_right_side.stl</uri>
          </mesh>
        </geometry>
        <surface>
          <contact>
            <ode>
              <kp>1e+07</kp>
              <kd>1</kd>
              <max_vel>0</max_vel>
              <min_depth>0.001</min_depth>
            </ode>
          </contact>
          <friction>
            <ode>
              <mu>4</mu>
              <mu2>4</mu2>
            </ode>
          </friction>
        </surface>
      </collision>
      <visual name='upper3_visual'>
        <pose frame=''>0 0 0 0 -0 0</pose>
        <geometry>
          <mesh>
            <scale>1 1 1</scale>
            <uri>file:///home/prakhargoel/Desktop/Mitacs/QuadSdk/catkin_ws/src/quad-sdk/quad_simulator/solo_description/meshes/stl/with_foot/solo_upper_leg_right_side.stl</uri>
          </mesh>
        </geometry>
        <material>
          <script>
            <name>Gazebo/Grey</name>
            <uri>file://media/materials/scripts/gazebo.material</uri>
          </script>
        </material>
      </visual>
      <velocity_decay/>
      <gravity>1</gravity>
      <velocity_decay/>
    </link>
    <joint name='6' type='revolute'>
      <child>upper3</child>
      <parent>hip3</parent>
      <axis>
        <xyz>0 1 0</xyz>
        <limit>
          <lower>-10</lower>
          <upper>10</upper>
          <effort>1000</effort>
          <velocity>1000</velocity>
        </limit>
        <dynamics>
          <damping>0</damping>
          <friction>0</friction>
          <spring_reference>0</spring_reference>
          <spring_stiffness>0</spring_stiffness>
        </dynamics>
        <use_parent_model_frame>0</use_parent_model_frame>
      </axis>
    </joint>
    <link name='lower3'>
      <pose frame=''>-0.1946 -0.13895 -0.16 0 -0 0</pose>
      <inertial>
        <pose frame=''>0 0.004951 -0.102249 0 -0 0</pose>
        <mass>0.0376361</mass>
        <inertia>
          <ixx>0.000150245</ixx>
          <ixy>0</ixy>
          <ixz>0</ixz>
          <iyy>0.000149139</iyy>
          <iyz>-9.37015e-06</iyz>
          <izz>4.11611e-06</izz>
        </inertia>
      </inertial>
      <collision name='lower3_collision'>
        <pose frame=''>0 0 0 0 -0 0</pose>
        <geometry>
          <mesh>
            <scale>1 1 1</scale>
            <uri>file:///home/prakhargoel/Desktop/Mitacs/QuadSdk/catkin_ws/src/quad-sdk/quad_simulator/solo_description/meshes/stl/with_foot/solo_lower_leg_right_side.stl</uri>
          </mesh>
        </geometry>
        <surface>
          <contact>
            <ode>
              <kp>1e+07</kp>
              <kd>1</kd>
              <max_vel>0</max_vel>
              <min_depth>0.001</min_depth>
            </ode>
          </contact>
          <friction>
            <ode>
              <mu>4</mu>
              <mu2>4</mu2>
            </ode>
          </friction>
        </surface>
      </collision>
      <collision name='lower3_fixed_joint_lump__toe3_collision_1'>
        <pose frame=''>0 -0.008 -0.16 0 -0 0</pose>
        <geometry>
          <mesh>
            <scale>1 1 1</scale>
            <uri>file:///home/prakhargoel/Desktop/Mitacs/QuadSdk/catkin_ws/src/quad-sdk/quad_simulator/solo_description/meshes/stl/with_foot/solo_foot.stl</uri>
          </mesh>
        </geometry>
        <surface>
          <bounce>
            <restitution_coefficient>0</restitution_coefficient>
            <threshold>1e+06</threshold>
          </bounce>
          <friction>
            <ode>
              <mu>0.5</mu>
              <mu2>0.5</mu2>
            </ode>
            <bullet>
              <rolling_friction>0.3</rolling_friction>
              <friction2>50</friction2>
            </bullet>
          </friction>
          <contact>
            <bullet>
              <kp>30000</kp>
              <kd>1000</kd>
              <split_impulse>1</split_impulse>
              <split_impulse_penetration_threshold>-0.01</split_impulse_penetration_threshold>
            </bullet>
            <ode>
              <kp>30000</kp>
              <kd>1000</kd>
            </ode>
          </contact>
        </surface>
      </collision>
      <visual name='lower3_visual'>
        <pose frame=''>0 0 0 0 -0 0</pose>
        <geometry>
          <mesh>
            <scale>1 1 1</scale>
            <uri>file:///home/prakhargoel/Desktop/Mitacs/QuadSdk/catkin_ws/src/quad-sdk/quad_simulator/solo_description/meshes/stl/with_foot/solo_lower_leg_right_side.stl</uri>
          </mesh>
        </geometry>
        <material>
          <script>
            <name>Gazebo/Grey</name>
            <uri>file://media/materials/scripts/gazebo.material</uri>
          </script>
        </material>
      </visual>
      <visual name='lower3_fixed_joint_lump__toe3_visual_1'>
        <pose frame=''>0 -0.008 -0.16 0 -0 0</pose>
        <geometry>
          <mesh>
            <scale>1 1 1</scale>
            <uri>file:///home/prakhargoel/Desktop/Mitacs/QuadSdk/catkin_ws/src/quad-sdk/quad_simulator/solo_description/meshes/stl/with_foot/solo_foot.stl</uri>
          </mesh>
        </geometry>
        <material>
          <script>
            <name>Gazebo/DarkGray</name>
            <uri>file://media/materials/scripts/gazebo.material</uri>
          </script>
        </material>
      </visual>
      <velocity_decay/>
      <velocity_decay/>
      <gravity>1</gravity>
      <velocity_decay/>
    </link>
    <joint name='7' type='revolute'>
      <child>lower3</child>
      <parent>upper3</parent>
      <axis>
        <xyz>0 1 0</xyz>
        <limit>
          <lower>-10</lower>
          <upper>10</upper>
          <effort>1000</effort>
          <velocity>1000</velocity>
        </limit>
        <dynamics>
          <damping>0</damping>
          <friction>0</friction>
          <spring_reference>0</spring_reference>
          <spring_stiffness>0</spring_stiffness>
        </dynamics>
        <use_parent_model_frame>0</use_parent_model_frame>
      </axis>
    </joint>
  
     <link name='toe0'>
      <pose frame=''>0.1946 0.13895 -0.16 0 -0 0</pose>
      <inertial>
        <pose>0 0.007899 -0.102249 0 -0 0</pose>
        <mass>0.0376361</mass>
        <inertia>
          <ixx>0.000148819</ixx>
          <ixy>0</ixy>
          <ixz>0</ixz>
          <iyy>0.000149139</iyy>
          <iyz>3.09919e-06</iyz>
          <izz>2.69009e-06</izz>
        </inertia>
      </inertial>
      <collision name='toe0_collision'>
        <pose frame=''>0 0 0 0 -0 0</pose>
        <geometry>
          <sphere>
            <radius>0.02</radius>
          </sphere>
        </geometry>
        <surface>
          <bounce>
            <restitution_coefficient>0</restitution_coefficient>
            <threshold>1e+06</threshold>
          </bounce>
          <friction>
            <ode>
              <mu>0.5</mu>
              <mu2>0.5</mu2>
            </ode>
            <bullet>
              <rolling_friction>0.3</rolling_friction>
              <friction2>50</friction2>
            </bullet>
          </friction>
          <contact>
            <bullet>
              <kp>30000</kp>
              <kd>1000</kd>
              <split_impulse>1</split_impulse>
              <split_impulse_penetration_threshold>-0.01</split_impulse_penetration_threshold>
            </bullet>
            <ode>
              <kp>30000</kp>
              <kd>1000</kd>
            </ode>
          </contact>
        </surface>
      </collision>
  
      <visual name='toe0_visual'>
        <pose frame=''>0 0 0 0 -0 0</pose>
        <geometry>
          <sphere>
            <radius>0.02</radius>
          </sphere>
        </geometry>
        <material>
          <script>
            <name>Gazebo/Black</name>
            <uri>file://media/materials/scripts/gazebo.material</uri>
          </script>
        </material>
      </visual>
      <gravity>1</gravity>
      <velocity_decay />
    </link>
    <joint name='jtoe0' type='fixed'>
      <child>toe0</child>
      <parent>lower0</parent>
    </joint>

    <link name='toe2'>
      <pose frame=''>0.1946 -0.13895 -0.16 0 -0 0</pose>
      <inertial>
        <pose>0 0.004951 -0.102249 0 -0 0</pose>
        <mass>0.0376361</mass>
        <inertia>
          <ixx>0.000150245</ixx>
          <ixy>0</ixy>
          <ixz>0</ixz>
          <iyy>0.000149139</iyy>
          <iyz>-9.37015e-06</iyz>
          <izz>4.11611e-06</izz>
        </inertia>
      </inertial>
      <collision name='toe2_collision'>
        <pose frame=''>0 0 0 0 -0 0</pose>
        <geometry>
          <sphere>
            <radius>0.02</radius>
          </sphere>
        </geometry>
        <surface>
          <bounce>
            <restitution_coefficient>0</restitution_coefficient>
            <threshold>1e+06</threshold>
          </bounce>
          <friction>
            <ode>
              <mu>0.5</mu>
              <mu2>0.5</mu2>
            </ode>
            <bullet>
              <rolling_friction>0.3</rolling_friction>
              <friction2>50</friction2>
            </bullet>
          </friction>
          <contact>
            <bullet>
              <kp>30000</kp>
              <kd>1000</kd>
              <split_impulse>1</split_impulse>
              <split_impulse_penetration_threshold>-0.01</split_impulse_penetration_threshold>
            </bullet>
            <ode>
              <kp>30000</kp>
              <kd>1000</kd>
            </ode>
          </contact>
        </surface>
      </collision>
      <visual name='toe2_visual'>
        <pose frame=''>0 0 0 0 -0 0</pose>
        <geometry>
          <sphere>
            <radius>0.02</radius>
          </sphere>
        </geometry>
        <material>
          <script>
            <name>Gazebo/Black</name>
            <uri>file://media/materials/scripts/gazebo.material</uri>
          </script>
        </material>
      </visual>
      <gravity>1</gravity>
      <velocity_decay />
    </link>
    <joint name='jtoe1' type='fixed'>
      <child>toe1</child>
      <parent>lower1</parent>
    </joint>

    <link name='toe1'>
      <pose frame=''>-0.1946 0.1015 0 0 -0 0</pose>      
        <inertial>
        <pose>0 0.007899 -0.102249 0 -0 0</pose>
        <mass>0.0376361</mass>
        <inertia>
          <ixx>0.000148819</ixx>
          <ixy>0</ixy>
          <ixz>0</ixz>
          <iyy>0.000149139</iyy>
          <iyz>3.09919e-06</iyz>
          <izz>2.69009e-06</izz>
        </inertia>
      </inertial>
      <collision name='toe1_collision'>
        <pose frame=''>0 0 0 0 -0 0</pose>
        <geometry>
          <sphere>
            <radius>0.02</radius>
          </sphere>
        </geometry>
        <surface>
          <bounce>
            <restitution_coefficient>0</restitution_coefficient>
            <threshold>1e+06</threshold>
          </bounce>
          <friction>
            <ode>
              <mu>0.5</mu>
              <mu2>0.5</mu2>
            </ode>
            <bullet>
              <rolling_friction>0.3</rolling_friction>
              <friction2>50</friction2>
            </bullet>
          </friction>
          <contact>
            <bullet>
              <kp>30000</kp>
              <kd>1000</kd>
              <split_impulse>1</split_impulse>
              <split_impulse_penetration_threshold>-0.01</split_impulse_penetration_threshold>
            </bullet>
            <ode>
              <kp>30000</kp>
              <kd>1000</kd>
            </ode>
          </contact>
        </surface>
      </collision>
      <visual name='toe1_visual'>
        <pose frame=''>0 0 0 0 -0 0</pose>
        <geometry>
          <sphere>
            <radius>0.02</radius>
          </sphere>
        </geometry>
        <material>
          <script>
            <name>Gazebo/Black</name>
            <uri>file://media/materials/scripts/gazebo.material</uri>
          </script>
        </material>
      </visual>
      <gravity>1</gravity>
      <velocity_decay />
    </link>
    <joint name='jtoe2' type='fixed'>
      <child>toe2</child>
      <parent>lower1</parent>
    </joint>

    <link name='toe3'>
      <pose frame=''>-0.1946 -0.1015 0 0 -0 0</pose>      
      <inertial>
        <pose>0 0.004951 -0.102249 0 -0 0</pose>
        <mass>0.0376361</mass>
        <inertia>
          <ixx>0.000150245</ixx>
          <ixy>0</ixy>
          <ixz>0</ixz>
          <iyy>0.000149139</iyy>
          <iyz>-9.37015e-06</iyz>
          <izz>4.11611e-06</izz>
        </inertia>
      </inertial>
      <collision name='toe3_collision'>
        <pose frame=''>0 0 0 0 -0 0</pose>
        <geometry>
          <sphere>
            <radius>0.02</radius>
          </sphere>
        </geometry>
        <surface>
          <bounce>
            <restitution_coefficient>0</restitution_coefficient>
            <threshold>1e+06</threshold>
          </bounce>
          <friction>
            <ode>
              <mu>0.5</mu>
              <mu2>0.5</mu2>
            </ode>
            <bullet>
              <rolling_friction>0.3</rolling_friction>
              <friction2>50</friction2>
            </bullet>
          </friction>
          <contact>
            <bullet>
              <kp>30000</kp>
              <kd>1000</kd>
              <split_impulse>1</split_impulse>
              <split_impulse_penetration_threshold>-0.01</split_impulse_penetration_threshold>
            </bullet>
            <ode>
              <kp>30000</kp>
              <kd>1000</kd>
            </ode>
          </contact>
        </surface>
      </collision>
      <visual name='toe3_visual'>
        <pose frame=''>0 0 0 0 -0 0</pose>
        <geometry>
          <sphere>
            <radius>0.02</radius>
          </sphere>
        </geometry>
        <material>
          <script>
            <name>Gazebo/Black</name>
            <uri>file://media/materials/scripts/gazebo.material</uri>
          </script>
        </material>
      </visual>
      <gravity>1</gravity>
      <velocity_decay />
    </link>
    <joint name='jtoe3' type='fixed'>
      <child>toe3</child>
      <parent>lower3</parent>
    </joint>
    
    <plugin name='gazebo_ros_control' filename='libgazebo_ros_control.so'>
      <robotNamespace>/solo</robotNamespace>
      <robotSimType>gazebo_ros_control/DefaultRobotHWSim</robotSimType>
    </plugin>
    <plugin name='ground_truth_estimator' filename='libground_truth_estimator.so'>
      <updateRateHZ>500.0</updateRateHZ>
    </plugin>
    <static>0</static>
    <self_collide>1</self_collide>
  </model>
</sdf>
