<sdf version='1.6'>
  <model name='solo'>
    <link name='base_link'>
      <pose frame=''>0 0 0 0 -0 0</pose>
      <inertial>
        <pose frame=''>0 0 0 0 -0 0</pose>
        <mass>1.16115</mass>
        <inertia>
          <ixx>0.00578574</ixx>
          <ixy>0</ixy>
          <ixz>0</ixz>
          <iyy>0.0193811</iyy>
          <iyz>0</iyz>
          <izz>0.0247612</izz>
        </inertia>
      </inertial>
      <collision name='base_link_collision'>
        <pose frame=''>0 0 0 0 -0 0</pose>
        <geometry>
          <mesh>
            <scale>1 1 1</scale>
            <uri>file:///home/prakhargoel/Desktop/Mitacs/QuadSdk/catkin_ws/src/quad-sdk/quad_simulator/solo_description/meshes/stl/solo12/solo_12_base.stl</uri>
          </mesh>
        </geometry>
        <surface>
          <contact>
            <ode>
              <kp>1e+07</kp>
              <kd>1</kd>
              <max_vel>0</max_vel>
              <min_depth>0.001</min_depth>
            </ode>
          </contact>
          <friction>
            <ode>
              <mu>4</mu>
              <mu2>4</mu2>
            </ode>
          </friction>
        </surface>
      </collision>
      <visual name='base_link_visual'>
        <pose frame=''>0 0 0 0 -0 0</pose>
        <geometry>
          <mesh>
            <scale>1 1 1</scale>
            <uri>file:///home/prakhargoel/Desktop/Mitacs/QuadSdk/catkin_ws/src/quad-sdk/quad_simulator/solo_description/meshes/stl/solo12/solo_12_base.stl</uri>
          </mesh>
        </geometry>
        <material>
          <script>
            <name>Gazebo/White</name>
            <uri>file://media/materials/scripts/gazebo.material</uri>
          </script>
        </material>
      </visual>
      <velocity_decay/>
      <gravity>1</gravity>
      <sensor name='imu_sensor' type='imu'>
        <always_on>1</always_on>
        <visualize>1</visualize>
        <topic>__default_topic_</topic>
        <plugin name='imu_plugin' filename='libgazebo_ros_imu_sensor.so'>
          <topicName>imu</topicName>
          <bodyName>body</bodyName>
          <updateRateHZ>500.0</updateRateHZ>
          <gaussianNoise>0.0</gaussianNoise>
          <xyzOffset>0 0 0</xyzOffset>
          <rpyOffset>0 0 0</rpyOffset>
          <frameName>body</frameName>
          <initialOrientationAsReference>1</initialOrientationAsReference>
        </plugin>
        <pose frame=''>0 0 0 0 -0 0</pose>
      </sensor>
      <gravity>1</gravity>
      <velocity_decay/>
    </link>
    <link name='FL_SHOULDER'>
      <pose frame=''>0.1946 0.0875 0 0 -0 0</pose>
      <inertial>
        <pose frame=''>-0.078707 0.01 0 0 -0 0</pose>
        <mass>0.148538</mass>
        <inertia>
          <ixx>3.024e-05</ixx>
          <ixy>4.671e-05</ixy>
          <ixz>0</ixz>
          <iyy>0.00041193</iyy>
          <iyz>0</iyz>
          <izz>0.00041107</izz>
        </inertia>
      </inertial>
      <collision name='FL_SHOULDER_collision'>
        <pose frame=''>0.0195 0 0 0 -0 0</pose>
        <geometry>
          <mesh>
            <scale>1 1 1</scale>
            <uri>file:///home/prakhargoel/Desktop/Mitacs/QuadSdk/catkin_ws/src/quad-sdk/quad_simulator/solo_description/meshes/stl/solo12/solo12_hip_fe_fl.stl</uri>
          </mesh>
        </geometry>
        <surface>
          <contact>
            <ode/>
          </contact>
          <friction>
            <ode/>
          </friction>
        </surface>
      </collision>
      <visual name='FL_SHOULDER_visual'>
        <pose frame=''>0.0195 0 0 0 -0 0</pose>
        <geometry>
          <mesh>
            <scale>1 1 1</scale>
            <uri>file:///home/prakhargoel/Desktop/Mitacs/QuadSdk/catkin_ws/src/quad-sdk/quad_simulator/solo_description/meshes/stl/solo12/solo12_hip_fe_fl.stl</uri>
          </mesh>
        </geometry>
        <material>
          <script>
            <name>Gazebo/Gray</name>
            <uri>file://media/materials/scripts/gazebo.material</uri>
          </script>
        </material>
      </visual>
      <gravity>1</gravity>
      <velocity_decay/>
    </link>
    <joint name='FL_HAA' type='revolute'>
      <child>FL_SHOULDER</child>
      <parent>base_link</parent>
      <axis>
        <xyz>1 0 0</xyz>
        <limit>
          <lower>-10</lower>
          <upper>10</upper>
          <effort>1000</effort>
          <velocity>1000</velocity>
        </limit>
        <dynamics>
          <damping>0</damping>
          <friction>0</friction>
          <spring_reference>0</spring_reference>
          <spring_stiffness>0</spring_stiffness>
        </dynamics>
        <use_parent_model_frame>0</use_parent_model_frame>
      </axis>
    </joint>
    <link name='FL_UPPER_LEG'>
      <pose frame=''>0.1946 0.1015 0 0 -0 0</pose>
      <inertial>
        <pose frame=''>1.4e-05 0.019359 -0.078707 0 -0 0</pose>
        <mass>0.148538</mass>
        <inertia>
          <ixx>0.00041107</ixx>
          <ixy>0</ixy>
          <ixz>0</ixz>
          <iyy>0.00041193</iyy>
          <iyz>4.671e-05</iyz>
          <izz>3.024e-05</izz>
        </inertia>
      </inertial>
      <collision name='FL_UPPER_LEG_collision'>
        <pose frame=''>0 0 0 0 -0 0</pose>
        <geometry>
          <mesh>
            <scale>1 1 1</scale>
            <uri>file:///home/prakhargoel/Desktop/Mitacs/QuadSdk/catkin_ws/src/quad-sdk/quad_simulator/solo_description/meshes/stl/with_foot/solo_upper_leg_left_side.stl</uri>
          </mesh>
        </geometry>
        <surface>
          <contact>
            <ode>
              <kp>1e+07</kp>
              <kd>1</kd>
              <max_vel>0</max_vel>
              <min_depth>0.001</min_depth>
            </ode>
          </contact>
          <friction>
            <ode>
              <mu>4</mu>
              <mu2>4</mu2>
            </ode>
          </friction>
        </surface>
      </collision>
      <visual name='FL_UPPER_LEG_visual'>
        <pose frame=''>0 0 0 0 -0 0</pose>
        <geometry>
          <mesh>
            <scale>1 1 1</scale>
            <uri>file:///home/prakhargoel/Desktop/Mitacs/QuadSdk/catkin_ws/src/quad-sdk/quad_simulator/solo_description/meshes/stl/with_foot/solo_upper_leg_left_side.stl</uri>
          </mesh>
        </geometry>
        <material>
          <script>
            <name>Gazebo/Grey</name>
            <uri>file://media/materials/scripts/gazebo.material</uri>
          </script>
        </material>
      </visual>
      <velocity_decay/>
      <gravity>1</gravity>
      <velocity_decay/>
    </link>
    <joint name='FL_HFE' type='revolute'>
      <child>FL_UPPER_LEG</child>
      <parent>FL_SHOULDER</parent>
      <axis>
        <xyz>0 1 0</xyz>
        <limit>
          <lower>-10</lower>
          <upper>10</upper>
          <effort>1000</effort>
          <velocity>1000</velocity>
        </limit>
        <dynamics>
          <damping>0</damping>
          <friction>0</friction>
          <spring_reference>0</spring_reference>
          <spring_stiffness>0</spring_stiffness>
        </dynamics>
        <use_parent_model_frame>0</use_parent_model_frame>
      </axis>
    </joint>
    <link name='FL_LOWER_LEG'>
      <pose frame=''>0.1946 0.13895 -0.16 0 -0 0</pose>
      <inertial>
        <pose frame=''>0 0.007899 -0.102249 0 -0 0</pose>
        <mass>0.0376361</mass>
        <inertia>
          <ixx>0.000148819</ixx>
          <ixy>0</ixy>
          <ixz>0</ixz>
          <iyy>0.000149139</iyy>
          <iyz>3.09919e-06</iyz>
          <izz>2.69009e-06</izz>
        </inertia>
      </inertial>
      <collision name='FL_LOWER_LEG_collision'>
        <pose frame=''>0 0 0 0 -0 0</pose>
        <geometry>
          <mesh>
            <scale>1 1 1</scale>
            <uri>file:///home/prakhargoel/Desktop/Mitacs/QuadSdk/catkin_ws/src/quad-sdk/quad_simulator/solo_description/meshes/stl/with_foot/solo_lower_leg_left_side.stl</uri>
          </mesh>
        </geometry>
        <surface>
          <contact>
            <ode>
              <kp>1e+07</kp>
              <kd>1</kd>
              <max_vel>0</max_vel>
              <min_depth>0.001</min_depth>
            </ode>
          </contact>
          <friction>
            <ode>
              <mu>4</mu>
              <mu2>4</mu2>
            </ode>
          </friction>
        </surface>
      </collision>
      <collision name='FL_LOWER_LEG_fixed_joint_lump__FL_FOOT_collision_1'>
        <pose frame=''>0 0.008 -0.16 0 -0 0</pose>
        <geometry>
          <mesh>
            <scale>1 1 1</scale>
            <uri>file:///home/prakhargoel/Desktop/Mitacs/QuadSdk/catkin_ws/src/quad-sdk/quad_simulator/solo_description/meshes/stl/with_foot/solo_foot.stl</uri>
          </mesh>
        </geometry>
        <surface>
          <contact>
            <ode>
              <kp>1e+07</kp>
              <kd>1</kd>
              <max_vel>0</max_vel>
              <min_depth>0.001</min_depth>
            </ode>
          </contact>
          <friction>
            <ode>
              <mu>4</mu>
              <mu2>4</mu2>
            </ode>
          </friction>
        </surface>
      </collision>
      <visual name='FL_LOWER_LEG_visual'>
        <pose frame=''>0 0 0 0 -0 0</pose>
        <geometry>
          <mesh>
            <scale>1 1 1</scale>
            <uri>file:///home/prakhargoel/Desktop/Mitacs/QuadSdk/catkin_ws/src/quad-sdk/quad_simulator/solo_description/meshes/stl/with_foot/solo_lower_leg_left_side.stl</uri>
          </mesh>
        </geometry>
        <material>
          <script>
            <name>Gazebo/DarkGrey</name>
            <uri>file://media/materials/scripts/gazebo.material</uri>
          </script>
        </material>
      </visual>
      <visual name='FL_LOWER_LEG_fixed_joint_lump__FL_FOOT_visual_1'>
        <pose frame=''>0 0.008 -0.16 0 -0 0</pose>
        <geometry>
          <mesh>
            <scale>1 1 1</scale>
            <uri>file:///home/prakhargoel/Desktop/Mitacs/QuadSdk/catkin_ws/src/quad-sdk/quad_simulator/solo_description/meshes/stl/with_foot/solo_foot.stl</uri>
          </mesh>
        </geometry>
        <material>
          <script>
            <name>Gazebo/DarkGrey</name>
            <uri>file://media/materials/scripts/gazebo.material</uri>
          </script>
        </material>
      </visual>
      <velocity_decay/>
      <velocity_decay/>
      <velocity_decay/>
      <gravity>1</gravity>
      <velocity_decay/>
    </link>
    <joint name='FL_KFE' type='revolute'>
      <child>FL_LOWER_LEG</child>
      <parent>FL_UPPER_LEG</parent>
      <axis>
        <xyz>0 1 0</xyz>
        <limit>
          <lower>-10</lower>
          <upper>10</upper>
          <effort>1000</effort>
          <velocity>1000</velocity>
        </limit>
        <dynamics>
          <damping>0</damping>
          <friction>0</friction>
          <spring_reference>0</spring_reference>
          <spring_stiffness>0</spring_stiffness>
        </dynamics>
        <use_parent_model_frame>0</use_parent_model_frame>
      </axis>
    </joint>
    <link name='FR_SHOULDER'>
      <pose frame=''>0.1946 -0.0875 0 0 -0 0</pose>
      <inertial>
        <pose frame=''>-0.078707 -0.01 0 0 -0 0</pose>
        <mass>0.148538</mass>
        <inertia>
          <ixx>3.024e-05</ixx>
          <ixy>-4.671e-05</ixy>
          <ixz>0</ixz>
          <iyy>0.00041193</iyy>
          <iyz>0</iyz>
          <izz>0.00041107</izz>
        </inertia>
      </inertial>
      <collision name='FR_SHOULDER_collision'>
        <pose frame=''>0.0195 0 0 0 -0 0</pose>
        <geometry>
          <mesh>
            <scale>1 1 1</scale>
            <uri>file:///home/prakhargoel/Desktop/Mitacs/QuadSdk/catkin_ws/src/quad-sdk/quad_simulator/solo_description/meshes/stl/solo12/solo12_hip_fe_fr.stl</uri>
          </mesh>
        </geometry>
        <surface>
          <contact>
            <ode/>
          </contact>
          <friction>
            <ode/>
          </friction>
        </surface>
      </collision>
      <visual name='FR_SHOULDER_visual'>
        <pose frame=''>0.0195 0 0 0 -0 0</pose>
        <geometry>
          <mesh>
            <scale>1 1 1</scale>
            <uri>file:///home/prakhargoel/Desktop/Mitacs/QuadSdk/catkin_ws/src/quad-sdk/quad_simulator/solo_description/meshes/stl/solo12/solo12_hip_fe_fr.stl</uri>
          </mesh>
        </geometry>
        <material>
          <script>
            <name>Gazebo/Gray</name>
            <uri>file://media/materials/scripts/gazebo.material</uri>
          </script>
        </material>
      </visual>
      <gravity>1</gravity>
      <velocity_decay/>
    </link>
    <joint name='FR_HAA' type='revolute'>
      <child>FR_SHOULDER</child>
      <parent>base_link</parent>
      <axis>
        <xyz>1 0 0</xyz>
        <limit>
          <lower>-10</lower>
          <upper>10</upper>
          <effort>1000</effort>
          <velocity>1000</velocity>
        </limit>
        <dynamics>
          <damping>0</damping>
          <friction>0</friction>
          <spring_reference>0</spring_reference>
          <spring_stiffness>0</spring_stiffness>
        </dynamics>
        <use_parent_model_frame>0</use_parent_model_frame>
      </axis>
    </joint>
    <link name='FR_UPPER_LEG'>
      <pose frame=''>0.1946 -0.1015 0 0 -0 0</pose>
      <inertial>
        <pose frame=''>-1.4e-05 -0.019359 -0.078707 0 -0 0</pose>
        <mass>0.148538</mass>
        <inertia>
          <ixx>0.00041107</ixx>
          <ixy>0</ixy>
          <ixz>0</ixz>
          <iyy>0.00041193</iyy>
          <iyz>-4.671e-05</iyz>
          <izz>3.024e-05</izz>
        </inertia>
      </inertial>
      <collision name='FR_UPPER_LEG_collision'>
        <pose frame=''>0 0 0 0 -0 0</pose>
        <geometry>
          <mesh>
            <scale>1 1 1</scale>
            <uri>file:///home/prakhargoel/Desktop/Mitacs/QuadSdk/catkin_ws/src/quad-sdk/quad_simulator/solo_description/meshes/stl/with_foot/solo_upper_leg_right_side.stl</uri>
          </mesh>
        </geometry>
        <surface>
          <contact>
            <ode>
              <kp>1e+07</kp>
              <kd>1</kd>
              <max_vel>0</max_vel>
              <min_depth>0.001</min_depth>
            </ode>
          </contact>
          <friction>
            <ode>
              <mu>4</mu>
              <mu2>4</mu2>
            </ode>
          </friction>
        </surface>
      </collision>
      <visual name='FR_UPPER_LEG_visual'>
        <pose frame=''>0 0 0 0 -0 0</pose>
        <geometry>
          <mesh>
            <scale>1 1 1</scale>
            <uri>file:///home/prakhargoel/Desktop/Mitacs/QuadSdk/catkin_ws/src/quad-sdk/quad_simulator/solo_description/meshes/stl/with_foot/solo_upper_leg_right_side.stl</uri>
          </mesh>
        </geometry>
        <material>
          <script>
            <name>Gazebo/Grey</name>
            <uri>file://media/materials/scripts/gazebo.material</uri>
          </script>
        </material>
      </visual>
      <velocity_decay/>
      <gravity>1</gravity>
      <velocity_decay/>
    </link>
    <joint name='FR_HFE' type='revolute'>
      <child>FR_UPPER_LEG</child>
      <parent>FR_SHOULDER</parent>
      <axis>
        <xyz>0 1 0</xyz>
        <limit>
          <lower>-10</lower>
          <upper>10</upper>
          <effort>1000</effort>
          <velocity>1000</velocity>
        </limit>
        <dynamics>
          <damping>0</damping>
          <friction>0</friction>
          <spring_reference>0</spring_reference>
          <spring_stiffness>0</spring_stiffness>
        </dynamics>
        <use_parent_model_frame>0</use_parent_model_frame>
      </axis>
    </joint>
    <link name='FR_LOWER_LEG'>
      <pose frame=''>0.1946 -0.13895 -0.16 0 -0 0</pose>
      <inertial>
        <pose frame=''>0 0.004951 -0.102249 0 -0 0</pose>
        <mass>0.0376361</mass>
        <inertia>
          <ixx>0.000150245</ixx>
          <ixy>0</ixy>
          <ixz>0</ixz>
          <iyy>0.000149139</iyy>
          <iyz>-9.37015e-06</iyz>
          <izz>4.11611e-06</izz>
        </inertia>
      </inertial>
      <collision name='FR_LOWER_LEG_collision'>
        <pose frame=''>0 0 0 0 -0 0</pose>
        <geometry>
          <mesh>
            <scale>1 1 1</scale>
            <uri>file:///home/prakhargoel/Desktop/Mitacs/QuadSdk/catkin_ws/src/quad-sdk/quad_simulator/solo_description/meshes/stl/with_foot/solo_lower_leg_right_side.stl</uri>
          </mesh>
        </geometry>
        <surface>
          <contact>
            <ode>
              <kp>1e+07</kp>
              <kd>1</kd>
              <max_vel>0</max_vel>
              <min_depth>0.001</min_depth>
            </ode>
          </contact>
          <friction>
            <ode>
              <mu>4</mu>
              <mu2>4</mu2>
            </ode>
          </friction>
        </surface>
      </collision>
      <collision name='FR_LOWER_LEG_fixed_joint_lump__FR_FOOT_collision_1'>
        <pose frame=''>0 -0.008 -0.16 0 -0 0</pose>
        <geometry>
          <mesh>
            <scale>1 1 1</scale>
            <uri>file:///home/prakhargoel/Desktop/Mitacs/QuadSdk/catkin_ws/src/quad-sdk/quad_simulator/solo_description/meshes/stl/with_foot/solo_foot.stl</uri>
          </mesh>
        </geometry>
        <surface>
          <contact>
            <ode>
              <kp>1e+07</kp>
              <kd>1</kd>
              <max_vel>0</max_vel>
              <min_depth>0.001</min_depth>
            </ode>
          </contact>
          <friction>
            <ode>
              <mu>4</mu>
              <mu2>4</mu2>
            </ode>
          </friction>
        </surface>
      </collision>
      <visual name='FR_LOWER_LEG_visual'>
        <pose frame=''>0 0 0 0 -0 0</pose>
        <geometry>
          <mesh>
            <scale>1 1 1</scale>
            <uri>file:///home/prakhargoel/Desktop/Mitacs/QuadSdk/catkin_ws/src/quad-sdk/quad_simulator/solo_description/meshes/stl/with_foot/solo_lower_leg_right_side.stl</uri>
          </mesh>
        </geometry>
        <material>
          <script>
            <name>Gazebo/Grey</name>
            <uri>file://media/materials/scripts/gazebo.material</uri>
          </script>
        </material>
      </visual>
      <visual name='FR_LOWER_LEG_fixed_joint_lump__FR_FOOT_visual_1'>
        <pose frame=''>0 -0.008 -0.16 0 -0 0</pose>
        <geometry>
          <mesh>
            <scale>1 1 1</scale>
            <uri>file:///home/prakhargoel/Desktop/Mitacs/QuadSdk/catkin_ws/src/quad-sdk/quad_simulator/solo_description/meshes/stl/with_foot/solo_foot.stl</uri>
          </mesh>
        </geometry>
        <material>
          <script>
            <name>Gazebo/Grey</name>
            <uri>file://media/materials/scripts/gazebo.material</uri>
          </script>
        </material>
      </visual>
      <velocity_decay/>
      <velocity_decay/>
      <velocity_decay/>
      <gravity>1</gravity>
      <velocity_decay/>
    </link>
    <joint name='FR_KFE' type='revolute'>
      <child>FR_LOWER_LEG</child>
      <parent>FR_UPPER_LEG</parent>
      <axis>
        <xyz>0 1 0</xyz>
        <limit>
          <lower>-10</lower>
          <upper>10</upper>
          <effort>1000</effort>
          <velocity>1000</velocity>
        </limit>
        <dynamics>
          <damping>0</damping>
          <friction>0</friction>
          <spring_reference>0</spring_reference>
          <spring_stiffness>0</spring_stiffness>
        </dynamics>
        <use_parent_model_frame>0</use_parent_model_frame>
      </axis>
    </joint>
    <link name='HL_SHOULDER'>
      <pose frame=''>-0.1946 0.0875 0 0 -0 0</pose>
      <inertial>
        <pose frame=''>0.078707 0.01 0 0 -0 0</pose>
        <mass>0.148538</mass>
        <inertia>
          <ixx>3.024e-05</ixx>
          <ixy>4.671e-05</ixy>
          <ixz>0</ixz>
          <iyy>0.00041193</iyy>
          <iyz>0</iyz>
          <izz>0.00041107</izz>
        </inertia>
      </inertial>
      <collision name='HL_SHOULDER_collision'>
        <pose frame=''>-0.0195 0 0 0 -0 0</pose>
        <geometry>
          <mesh>
            <scale>1 1 1</scale>
            <uri>file:///home/prakhargoel/Desktop/Mitacs/QuadSdk/catkin_ws/src/quad-sdk/quad_simulator/solo_description/meshes/stl/solo12/solo12_hip_fe_hl.stl</uri>
          </mesh>
        </geometry>
        <surface>
          <contact>
            <ode/>
          </contact>
          <friction>
            <ode/>
          </friction>
        </surface>
      </collision>
      <visual name='HL_SHOULDER_visual'>
        <pose frame=''>-0.0195 0 0 0 -0 0</pose>
        <geometry>
          <mesh>
            <scale>1 1 1</scale>
            <uri>file:///home/prakhargoel/Desktop/Mitacs/QuadSdk/catkin_ws/src/quad-sdk/quad_simulator/solo_description/meshes/stl/solo12/solo12_hip_fe_hl.stl</uri>
          </mesh>
        </geometry>
        <material>
          <script>
            <name>Gazebo/Gray</name>
            <uri>file://media/materials/scripts/gazebo.material</uri>
          </script>
        </material>
      </visual>
      <gravity>1</gravity>
      <velocity_decay/>
    </link>
    <joint name='HL_HAA' type='revolute'>
      <child>HL_SHOULDER</child>
      <parent>base_link</parent>
      <axis>
        <xyz>1 0 0</xyz>
        <limit>
          <lower>-10</lower>
          <upper>10</upper>
          <effort>1000</effort>
          <velocity>1000</velocity>
        </limit>
        <dynamics>
          <damping>0</damping>
          <friction>0</friction>
          <spring_reference>0</spring_reference>
          <spring_stiffness>0</spring_stiffness>
        </dynamics>
        <use_parent_model_frame>0</use_parent_model_frame>
      </axis>
    </joint>
    <link name='HL_UPPER_LEG'>
      <pose frame=''>-0.1946 0.1015 0 0 -0 0</pose>
      <inertial>
        <pose frame=''>1.4e-05 0.019359 -0.078707 0 -0 0</pose>
        <mass>0.148538</mass>
        <inertia>
          <ixx>0.00041107</ixx>
          <ixy>0</ixy>
          <ixz>0</ixz>
          <iyy>0.00041193</iyy>
          <iyz>4.671e-05</iyz>
          <izz>3.024e-05</izz>
        </inertia>
      </inertial>
      <collision name='HL_UPPER_LEG_collision'>
        <pose frame=''>0 0 0 0 -0 0</pose>
        <geometry>
          <mesh>
            <scale>1 1 1</scale>
            <uri>file:///home/prakhargoel/Desktop/Mitacs/QuadSdk/catkin_ws/src/quad-sdk/quad_simulator/solo_description/meshes/stl/with_foot/solo_upper_leg_left_side.stl</uri>
          </mesh>
        </geometry>
        <surface>
          <contact>
            <ode>
              <kp>1e+07</kp>
              <kd>1</kd>
              <max_vel>0</max_vel>
              <min_depth>0.001</min_depth>
            </ode>
          </contact>
          <friction>
            <ode>
              <mu>4</mu>
              <mu2>4</mu2>
            </ode>
          </friction>
        </surface>
      </collision>
      <visual name='HL_UPPER_LEG_visual'>
        <pose frame=''>0 0 0 0 -0 0</pose>
        <geometry>
          <mesh>
            <scale>1 1 1</scale>
            <uri>file:///home/prakhargoel/Desktop/Mitacs/QuadSdk/catkin_ws/src/quad-sdk/quad_simulator/solo_description/meshes/stl/with_foot/solo_upper_leg_left_side.stl</uri>
          </mesh>
        </geometry>
        <material>
          <script>
            <name>Gazebo/DarkGrey</name>
            <uri>file://media/materials/scripts/gazebo.material</uri>
          </script>
        </material>
      </visual>
      <velocity_decay/>
      <gravity>1</gravity>
      <velocity_decay/>
    </link>
    <joint name='HL_HFE' type='revolute'>
      <child>HL_UPPER_LEG</child>
      <parent>HL_SHOULDER</parent>
      <axis>
        <xyz>0 1 0</xyz>
        <limit>
          <lower>-10</lower>
          <upper>10</upper>
          <effort>1000</effort>
          <velocity>1000</velocity>
        </limit>
        <dynamics>
          <damping>0</damping>
          <friction>0</friction>
          <spring_reference>0</spring_reference>
          <spring_stiffness>0</spring_stiffness>
        </dynamics>
        <use_parent_model_frame>0</use_parent_model_frame>
      </axis>
    </joint>
    <link name='HL_LOWER_LEG'>
      <pose frame=''>-0.1946 0.13895 -0.16 0 -0 0</pose>
      <inertial>
        <pose frame=''>0 0.007899 -0.102249 0 -0 0</pose>
        <mass>0.0376361</mass>
        <inertia>
          <ixx>0.000148819</ixx>
          <ixy>0</ixy>
          <ixz>0</ixz>
          <iyy>0.000149139</iyy>
          <iyz>3.09919e-06</iyz>
          <izz>2.69009e-06</izz>
        </inertia>
      </inertial>
      <collision name='HL_LOWER_LEG_collision'>
        <pose frame=''>0 0 0 0 -0 0</pose>
        <geometry>
          <mesh>
            <scale>1 1 1</scale>
            <uri>file:///home/prakhargoel/Desktop/Mitacs/QuadSdk/catkin_ws/src/quad-sdk/quad_simulator/solo_description/meshes/stl/with_foot/solo_lower_leg_left_side.stl</uri>
          </mesh>
        </geometry>
        <surface>
          <contact>
            <ode>
              <kp>1e+07</kp>
              <kd>1</kd>
              <max_vel>0</max_vel>
              <min_depth>0.001</min_depth>
            </ode>
          </contact>
          <friction>
            <ode>
              <mu>4</mu>
              <mu2>4</mu2>
            </ode>
          </friction>
        </surface>
      </collision>
      <collision name='HL_LOWER_LEG_fixed_joint_lump__HL_FOOT_collision_1'>
        <pose frame=''>0 0.008 -0.16 0 -0 0</pose>
        <geometry>
          <mesh>
            <scale>1 1 1</scale>
            <uri>file:///home/prakhargoel/Desktop/Mitacs/QuadSdk/catkin_ws/src/quad-sdk/quad_simulator/solo_description/meshes/stl/with_foot/solo_foot.stl</uri>
          </mesh>
        </geometry>
        <surface>
          <contact>
            <ode>
              <kp>1e+07</kp>
              <kd>1</kd>
              <max_vel>0</max_vel>
              <min_depth>0.001</min_depth>
            </ode>
          </contact>
          <friction>
            <ode>
              <mu>4</mu>
              <mu2>4</mu2>
            </ode>
          </friction>
        </surface>
      </collision>
      <visual name='HL_LOWER_LEG_visual'>
        <pose frame=''>0 0 0 0 -0 0</pose>
        <geometry>
          <mesh>
            <scale>1 1 1</scale>
            <uri>file:///home/prakhargoel/Desktop/Mitacs/QuadSdk/catkin_ws/src/quad-sdk/quad_simulator/solo_description/meshes/stl/with_foot/solo_lower_leg_left_side.stl</uri>
          </mesh>
        </geometry>
        <material>
          <script>
            <name>Gazebo/DarkGrey</name>
            <uri>file://media/materials/scripts/gazebo.material</uri>
          </script>
        </material>
      </visual>
      <visual name='HL_LOWER_LEG_fixed_joint_lump__HL_FOOT_visual_1'>
        <pose frame=''>0 0.008 -0.16 0 -0 0</pose>
        <geometry>
          <mesh>
            <scale>1 1 1</scale>
            <uri>file:///home/prakhargoel/Desktop/Mitacs/QuadSdk/catkin_ws/src/quad-sdk/quad_simulator/solo_description/meshes/stl/with_foot/solo_foot.stl</uri>
          </mesh>
        </geometry>
        <material>
          <script>
            <name>Gazebo/Grey</name>
            <uri>file://media/materials/scripts/gazebo.material</uri>
          </script>
        </material>
      </visual>
      <velocity_decay/>
      <velocity_decay/>
      <velocity_decay/>
      <gravity>1</gravity>
      <velocity_decay/>
    </link>
    <joint name='HL_KFE' type='revolute'>
      <child>HL_LOWER_LEG</child>
      <parent>HL_UPPER_LEG</parent>
      <axis>
        <xyz>0 1 0</xyz>
        <limit>
          <lower>-10</lower>
          <upper>10</upper>
          <effort>1000</effort>
          <velocity>1000</velocity>
        </limit>
        <dynamics>
          <damping>0</damping>
          <friction>0</friction>
          <spring_reference>0</spring_reference>
          <spring_stiffness>0</spring_stiffness>
        </dynamics>
        <use_parent_model_frame>0</use_parent_model_frame>
      </axis>
    </joint>
    <link name='HR_SHOULDER'>
      <pose frame=''>-0.1946 -0.0875 0 0 -0 0</pose>
      <inertial>
        <pose frame=''>0.078707 -0.01 0 0 -0 0</pose>
        <mass>0.148538</mass>
        <inertia>
          <ixx>3.024e-05</ixx>
          <ixy>-4.671e-05</ixy>
          <ixz>0</ixz>
          <iyy>0.00041193</iyy>
          <iyz>0</iyz>
          <izz>0.00041107</izz>
        </inertia>
      </inertial>
      <collision name='HR_SHOULDER_collision'>
        <pose frame=''>-0.0195 0 0 0 -0 0</pose>
        <geometry>
          <mesh>
            <scale>1 1 1</scale>
            <uri>file:///home/prakhargoel/Desktop/Mitacs/QuadSdk/catkin_ws/src/quad-sdk/quad_simulator/solo_description/meshes/stl/solo12/solo12_hip_fe_hr.stl</uri>
          </mesh>
        </geometry>
        <surface>
          <contact>
            <ode/>
          </contact>
          <friction>
            <ode/>
          </friction>
        </surface>
      </collision>
      <visual name='HR_SHOULDER_visual'>
        <pose frame=''>-0.0195 0 0 0 -0 0</pose>
        <geometry>
          <mesh>
            <scale>1 1 1</scale>
            <uri>file:///home/prakhargoel/Desktop/Mitacs/QuadSdk/catkin_ws/src/quad-sdk/quad_simulator/solo_description/meshes/stl/solo12/solo12_hip_fe_hr.stl</uri>
          </mesh>
        </geometry>
        <material>
          <script>
            <name>Gazebo/Gray</name>
            <uri>file://media/materials/scripts/gazebo.material</uri>
          </script>
        </material>
      </visual>
      <gravity>1</gravity>
      <velocity_decay/>
    </link>
    <joint name='HR_HAA' type='revolute'>
      <child>HR_SHOULDER</child>
      <parent>base_link</parent>
      <axis>
        <xyz>1 0 0</xyz>
        <limit>
          <lower>-10</lower>
          <upper>10</upper>
          <effort>1000</effort>
          <velocity>1000</velocity>
        </limit>
        <dynamics>
          <damping>0</damping>
          <friction>0</friction>
          <spring_reference>0</spring_reference>
          <spring_stiffness>0</spring_stiffness>
        </dynamics>
        <use_parent_model_frame>0</use_parent_model_frame>
      </axis>
    </joint>
    <link name='HR_UPPER_LEG'>
      <pose frame=''>-0.1946 -0.1015 0 0 -0 0</pose>
      <inertial>
        <pose frame=''>-1.4e-05 -0.019359 -0.078707 0 -0 0</pose>
        <mass>0.148538</mass>
        <inertia>
          <ixx>0.00041107</ixx>
          <ixy>0</ixy>
          <ixz>0</ixz>
          <iyy>0.00041193</iyy>
          <iyz>-4.671e-05</iyz>
          <izz>3.024e-05</izz>
        </inertia>
      </inertial>
      <collision name='HR_UPPER_LEG_collision'>
        <pose frame=''>0 0 0 0 -0 0</pose>
        <geometry>
          <mesh>
            <scale>1 1 1</scale>
            <uri>file:///home/prakhargoel/Desktop/Mitacs/QuadSdk/catkin_ws/src/quad-sdk/quad_simulator/solo_description/meshes/stl/with_foot/solo_upper_leg_right_side.stl</uri>
          </mesh>
        </geometry>
        <surface>
          <contact>
            <ode>
              <kp>1e+07</kp>
              <kd>1</kd>
              <max_vel>0</max_vel>
              <min_depth>0.001</min_depth>
            </ode>
          </contact>
          <friction>
            <ode>
              <mu>4</mu>
              <mu2>4</mu2>
            </ode>
          </friction>
        </surface>
      </collision>
      <visual name='HR_UPPER_LEG_visual'>
        <pose frame=''>0 0 0 0 -0 0</pose>
        <geometry>
          <mesh>
            <scale>1 1 1</scale>
            <uri>file:///home/prakhargoel/Desktop/Mitacs/QuadSdk/catkin_ws/src/quad-sdk/quad_simulator/solo_description/meshes/stl/with_foot/solo_upper_leg_right_side.stl</uri>
          </mesh>
        </geometry>
        <material>
          <script>
            <name>Gazebo/Grey</name>
            <uri>file://media/materials/scripts/gazebo.material</uri>
          </script>
        </material>
      </visual>
      <velocity_decay/>
      <gravity>1</gravity>
      <velocity_decay/>
    </link>
    <joint name='HR_HFE' type='revolute'>
      <child>HR_UPPER_LEG</child>
      <parent>HR_SHOULDER</parent>
      <axis>
        <xyz>0 1 0</xyz>
        <limit>
          <lower>-10</lower>
          <upper>10</upper>
          <effort>1000</effort>
          <velocity>1000</velocity>
        </limit>
        <dynamics>
          <damping>0</damping>
          <friction>0</friction>
          <spring_reference>0</spring_reference>
          <spring_stiffness>0</spring_stiffness>
        </dynamics>
        <use_parent_model_frame>0</use_parent_model_frame>
      </axis>
    </joint>
    <link name='HR_LOWER_LEG'>
      <pose frame=''>-0.1946 -0.13895 -0.16 0 -0 0</pose>
      <inertial>
        <pose frame=''>0 0.004951 -0.102249 0 -0 0</pose>
        <mass>0.0376361</mass>
        <inertia>
          <ixx>0.000150245</ixx>
          <ixy>0</ixy>
          <ixz>0</ixz>
          <iyy>0.000149139</iyy>
          <iyz>-9.37015e-06</iyz>
          <izz>4.11611e-06</izz>
        </inertia>
      </inertial>
      <collision name='HR_LOWER_LEG_collision'>
        <pose frame=''>0 0 0 0 -0 0</pose>
        <geometry>
          <mesh>
            <scale>1 1 1</scale>
            <uri>file:///home/prakhargoel/Desktop/Mitacs/QuadSdk/catkin_ws/src/quad-sdk/quad_simulator/solo_description/meshes/stl/with_foot/solo_lower_leg_right_side.stl</uri>
          </mesh>
        </geometry>
        <surface>
          <contact>
            <ode>
              <kp>1e+07</kp>
              <kd>1</kd>
              <max_vel>0</max_vel>
              <min_depth>0.001</min_depth>
            </ode>
          </contact>
          <friction>
            <ode>
              <mu>4</mu>
              <mu2>4</mu2>
            </ode>
          </friction>
        </surface>
      </collision>
      <collision name='HR_LOWER_LEG_fixed_joint_lump__HR_FOOT_collision_1'>
        <pose frame=''>0 -0.008 -0.16 0 -0 0</pose>
        <geometry>
          <mesh>
            <scale>1 1 1</scale>
            <uri>file:///home/prakhargoel/Desktop/Mitacs/QuadSdk/catkin_ws/src/quad-sdk/quad_simulator/solo_description/meshes/stl/with_foot/solo_foot.stl</uri>
          </mesh>
        </geometry>
        <surface>
          <contact>
            <ode>
              <kp>1e+07</kp>
              <kd>1</kd>
              <max_vel>0</max_vel>
              <min_depth>0.001</min_depth>
            </ode>
          </contact>
          <friction>
            <ode>
              <mu>4</mu>
              <mu2>4</mu2>
            </ode>
          </friction>
        </surface>
      </collision>
      <visual name='HR_LOWER_LEG_visual'>
        <pose frame=''>0 0 0 0 -0 0</pose>
        <geometry>
          <mesh>
            <scale>1 1 1</scale>
            <uri>file:///home/prakhargoel/Desktop/Mitacs/QuadSdk/catkin_ws/src/quad-sdk/quad_simulator/solo_description/meshes/stl/with_foot/solo_lower_leg_right_side.stl</uri>
          </mesh>
        </geometry>
        <material>
          <script>
            <name>Gazebo/Grey</name>
            <uri>file://media/materials/scripts/gazebo.material</uri>
          </script>
        </material>
      </visual>
      <visual name='HR_LOWER_LEG_fixed_joint_lump__HR_FOOT_visual_1'>
        <pose frame=''>0 -0.008 -0.16 0 -0 0</pose>
        <geometry>
          <mesh>
            <scale>1 1 1</scale>
            <uri>file:///home/prakhargoel/Desktop/Mitacs/QuadSdk/catkin_ws/src/quad-sdk/quad_simulator/solo_description/meshes/stl/with_foot/solo_foot.stl</uri>
          </mesh>
        </geometry>
        <material>
          <script>
            <name>Gazebo/Grey</name>
            <uri>file://media/materials/scripts/gazebo.material</uri>
          </script>
        </material>
      </visual>
      <velocity_decay/>
      <velocity_decay/>
      <velocity_decay/>
      <gravity>1</gravity>
      <velocity_decay/>
    </link>
    <joint name='HR_KFE' type='revolute'>
      <child>HR_LOWER_LEG</child>
      <parent>HR_UPPER_LEG</parent>
      <axis>
        <xyz>0 1 0</xyz>
        <limit>
          <lower>-10</lower>
          <upper>10</upper>
          <effort>1000</effort>
          <velocity>1000</velocity>
        </limit>
        <dynamics>
          <damping>0</damping>
          <friction>0</friction>
          <spring_reference>0</spring_reference>
          <spring_stiffness>0</spring_stiffness>
        </dynamics>
        <use_parent_model_frame>0</use_parent_model_frame>
      </axis>
    </joint>
    <plugin name='gazebo_ros_control' filename='libgazebo_ros_control.so'>
      <robotNamespace>/solo</robotNamespace>
      <robotSimType>gazebo_ros_control/DefaultRobotHWSim</robotSimType>
    </plugin>
    <plugin name='ground_truth_estimator' filename='libground_truth_estimator.so'>
      <updateRateHZ>500.0</updateRateHZ>
    </plugin>
    <static>0</static>
    <self_collide>1</self_collide>
  </model>
</sdf>
